{
 "cells": [
  {
   "cell_type": "markdown",
   "metadata": {},
   "source": [
    "Need to run \n",
    "\n",
    "`source activate tensorflow`"
   ]
  },
  {
   "cell_type": "code",
   "execution_count": 1,
   "metadata": {
    "collapsed": false
   },
   "outputs": [
    {
     "ename": "ImportError",
     "evalue": "Traceback (most recent call last):\n  File \"/home/btd17/miniconda2/lib/python2.7/site-packages/tensorflow/python/__init__.py\", line 61, in <module>\n    from tensorflow.python import pywrap_tensorflow\n  File \"/home/btd17/miniconda2/lib/python2.7/site-packages/tensorflow/python/pywrap_tensorflow.py\", line 28, in <module>\n    _pywrap_tensorflow = swig_import_helper()\n  File \"/home/btd17/miniconda2/lib/python2.7/site-packages/tensorflow/python/pywrap_tensorflow.py\", line 24, in swig_import_helper\n    _mod = imp.load_module('_pywrap_tensorflow', fp, pathname, description)\nImportError: /lib64/libc.so.6: version `GLIBC_2.16' not found (required by /home/btd17/miniconda2/lib/python2.7/site-packages/tensorflow/python/_pywrap_tensorflow.so)\n\n\nFailed to load the native TensorFlow runtime.\n\nSee https://github.com/tensorflow/tensorflow/blob/master/tensorflow/g3doc/get_started/os_setup.md#import_error\n\nfor some common reasons and solutions.  Include the entire stack trace\nabove this error message when asking for help.",
     "output_type": "error",
     "traceback": [
      "\u001b[0;31m---------------------------------------------------------------------------\u001b[0m",
      "\u001b[0;31mImportError\u001b[0m                               Traceback (most recent call last)",
      "\u001b[0;32m<ipython-input-1-38dcd51c26c2>\u001b[0m in \u001b[0;36m<module>\u001b[0;34m()\u001b[0m\n\u001b[1;32m      1\u001b[0m \u001b[0;32mimport\u001b[0m \u001b[0mnumpy\u001b[0m \u001b[0;32mas\u001b[0m \u001b[0mnp\u001b[0m\u001b[0;34m\u001b[0m\u001b[0m\n\u001b[1;32m      2\u001b[0m \u001b[0;32mfrom\u001b[0m \u001b[0msklearn\u001b[0m \u001b[0;32mimport\u001b[0m \u001b[0mmetrics\u001b[0m\u001b[0;34m\u001b[0m\u001b[0m\n\u001b[0;32m----> 3\u001b[0;31m \u001b[0;32mimport\u001b[0m \u001b[0mtensorflow\u001b[0m \u001b[0;32mas\u001b[0m \u001b[0mtf\u001b[0m\u001b[0;34m\u001b[0m\u001b[0m\n\u001b[0m\u001b[1;32m      4\u001b[0m \u001b[0;34m\u001b[0m\u001b[0m\n\u001b[1;32m      5\u001b[0m \u001b[0mlayers\u001b[0m \u001b[0;34m=\u001b[0m \u001b[0mtf\u001b[0m\u001b[0;34m.\u001b[0m\u001b[0mcontrib\u001b[0m\u001b[0;34m.\u001b[0m\u001b[0mlayers\u001b[0m\u001b[0;34m\u001b[0m\u001b[0m\n",
      "\u001b[0;32m/home/btd17/miniconda2/lib/python2.7/site-packages/tensorflow/__init__.py\u001b[0m in \u001b[0;36m<module>\u001b[0;34m()\u001b[0m\n\u001b[1;32m     22\u001b[0m \u001b[0;34m\u001b[0m\u001b[0m\n\u001b[1;32m     23\u001b[0m \u001b[0;31m# pylint: disable=wildcard-import\u001b[0m\u001b[0;34m\u001b[0m\u001b[0;34m\u001b[0m\u001b[0m\n\u001b[0;32m---> 24\u001b[0;31m \u001b[0;32mfrom\u001b[0m \u001b[0mtensorflow\u001b[0m\u001b[0;34m.\u001b[0m\u001b[0mpython\u001b[0m \u001b[0;32mimport\u001b[0m \u001b[0;34m*\u001b[0m\u001b[0;34m\u001b[0m\u001b[0m\n\u001b[0m\u001b[1;32m     25\u001b[0m \u001b[0;31m# pylint: enable=wildcard-import\u001b[0m\u001b[0;34m\u001b[0m\u001b[0;34m\u001b[0m\u001b[0m\n\u001b[1;32m     26\u001b[0m \u001b[0;34m\u001b[0m\u001b[0m\n",
      "\u001b[0;32m/home/btd17/miniconda2/lib/python2.7/site-packages/tensorflow/python/__init__.py\u001b[0m in \u001b[0;36m<module>\u001b[0;34m()\u001b[0m\n\u001b[1;32m     70\u001b[0m \u001b[0;32mfor\u001b[0m \u001b[0msome\u001b[0m \u001b[0mcommon\u001b[0m \u001b[0mreasons\u001b[0m \u001b[0;32mand\u001b[0m \u001b[0msolutions\u001b[0m\u001b[0;34m.\u001b[0m  \u001b[0mInclude\u001b[0m \u001b[0mthe\u001b[0m \u001b[0mentire\u001b[0m \u001b[0mstack\u001b[0m \u001b[0mtrace\u001b[0m\u001b[0;34m\u001b[0m\u001b[0m\n\u001b[1;32m     71\u001b[0m above this error message when asking for help.\"\"\" % traceback.format_exc()\n\u001b[0;32m---> 72\u001b[0;31m   \u001b[0;32mraise\u001b[0m \u001b[0mImportError\u001b[0m\u001b[0;34m(\u001b[0m\u001b[0mmsg\u001b[0m\u001b[0;34m)\u001b[0m\u001b[0;34m\u001b[0m\u001b[0m\n\u001b[0m\u001b[1;32m     73\u001b[0m \u001b[0;34m\u001b[0m\u001b[0m\n\u001b[1;32m     74\u001b[0m \u001b[0;31m# Protocol buffers\u001b[0m\u001b[0;34m\u001b[0m\u001b[0;34m\u001b[0m\u001b[0m\n",
      "\u001b[0;31mImportError\u001b[0m: Traceback (most recent call last):\n  File \"/home/btd17/miniconda2/lib/python2.7/site-packages/tensorflow/python/__init__.py\", line 61, in <module>\n    from tensorflow.python import pywrap_tensorflow\n  File \"/home/btd17/miniconda2/lib/python2.7/site-packages/tensorflow/python/pywrap_tensorflow.py\", line 28, in <module>\n    _pywrap_tensorflow = swig_import_helper()\n  File \"/home/btd17/miniconda2/lib/python2.7/site-packages/tensorflow/python/pywrap_tensorflow.py\", line 24, in swig_import_helper\n    _mod = imp.load_module('_pywrap_tensorflow', fp, pathname, description)\nImportError: /lib64/libc.so.6: version `GLIBC_2.16' not found (required by /home/btd17/miniconda2/lib/python2.7/site-packages/tensorflow/python/_pywrap_tensorflow.so)\n\n\nFailed to load the native TensorFlow runtime.\n\nSee https://github.com/tensorflow/tensorflow/blob/master/tensorflow/g3doc/get_started/os_setup.md#import_error\n\nfor some common reasons and solutions.  Include the entire stack trace\nabove this error message when asking for help."
     ]
    }
   ],
   "source": [
    "import numpy as np\n",
    "from sklearn import metrics\n",
    "import tensorflow as tf\n",
    "\n",
    "layers = tf.contrib.layers\n",
    "learn = tf.contrib.learn"
   ]
  },
  {
   "cell_type": "code",
   "execution_count": null,
   "metadata": {
    "collapsed": true
   },
   "outputs": [],
   "source": []
  }
 ],
 "metadata": {
  "anaconda-cloud": {},
  "kernelspec": {
   "display_name": "Python [default]",
   "language": "python",
   "name": "python2"
  }
 },
 "nbformat": 4,
 "nbformat_minor": 2
}
